---
epoch: 1733264067092
modelKey: gpt-4o-2024-11-20|openai
tags:
  - copilot-conversation
---

**user**: [ai_service.py](ai_service.py.md) [response_parsing.py](response_parsing.py.md) [docs.py](docs.py.md) [main.py](main.py.md) [repository_handler.py](repository_handler.py.md) ERROR: Error generating documentation: 'module_name'
[Timestamp: 2024/12/03 16:14:27]

**ai**: The error `'module_name'` seems to point to a missing or incorrect key in a dictionary where `module_name` is expected. From reviewing the provided code, there are potential locations where this could be happening:

1. **`docs.py` within `generate_documentation`**:
   ```python
   cache_key = f"doc:{self.context.module_path.stem}:{hash(self.context.source_code.encode())}"
   ```
   This line relies on `self.context.module_path` and `self.context.source_code` being set properly. If either is missing, it could lead to issues related to `module_name`.

2. **`main.py` within `process_file`**:
   ```python
   module_name = (
       file_path.stem  # Use the file's stem (e.g., 'example' for 'example.py')
       or file_path.name.split(".")[0]  # Fallback to a basic split
   )
   ```
   This defines `module_name`, but later:
   ```python
   if "module_name" not in context.metadata:
       context.metadata["module_name"] = module_name
   ```
   This ensures that `module_name` is added to the `metadata` dictionary if it doesn't exist, so this part is safeguarded, though an incorrect key access could throw an error.

3. **Potential issue in `ai_interaction.py` or `response_parsing.py`**:
   - If there's a misconfiguration when accessing `context.metadata` or any pre-processed extracted information requiring a `module_name` but it doesn't exist, this error could propagate.
   - Example:
     ```python
     "module_docstring": extraction_result.module_docstring,
     ```

4. **`repository_handler.py`**:
   When accessing file paths for repositories, `module_name` isn't directly used in this file but could propagate if repository interactions fail or `file_path.stem` isn't correctly resolved.

### Steps to Debug:
- **Add Logging**: Ensure logging shows what `context.metadata` or `extraction_result` contains at each step in `process_file` and `generate_documentation`. Check for any missing or incorrect keys.
- **Verify Context Details**:
  - Add debug logs where `context` is initialized:
    ```python
    self.logger.debug(f"Context metadata: {context.metadata}")
    ```
  - This would help verify `module_name` existence or lack thereof.
  
- **Ensure Fallback Logic**:
  - If `module_name` can be computed differently or default to a generic string value, update logic (`main.py`, `docs.py`).

Let me know how you'd like to proceed, whether specific safeguards or logging examples are needed!
[Timestamp: 2024/12/03 16:14:53]

**user**: [markdown_generator.py](markdown_generator.py.md) [docstring_processor.py](docstring_processor.py.md) is the error in these files?
[Timestamp: 2024/12/03 16:15:22]

**ai**: The provided context does not conclusively suggest that the error originates from `[[docstring_processor.py]]` or `[[markdown_generator.py]]`. However, there are potential areas in both files where the `module_name` or related context keys could result in a `KeyError` or similar issues, particularly within `[[markdown_generator.py]]`.

### **Potential Issues in `markdown_generator.py`**
1. **`_generate_header` Method**:
   ```python
   return f"# Module: {context['module_name']}"
   ```
   If `module_name` is missing from the context dictionary, this will raise a `KeyError`. 

2. **Overall Context (`generate` Method)**:
   The `context` dictionary used throughout the file heavily relies on certain keys (e.g., `module_name`, `file_path`, `description`) to exist. If these keys are missing, it can cause errors at runtime when attempting to format or generate markdown sections.

   For example:
   ```python
   return "\n".join([
       "## Overview",
       f"**File:** `{context['file_path']}`",
       f"**Description:** {context['description']}"
   ])
   ```

3. **AI Documentation Section**:
   The `_generate_ai_doc_section` method accesses nested dictionaries under `ai_documentation`. If the structure is not as expected or if keys (`summary`, `description`, etc.) are missing, the behavior might not be robust.

   Example:
   ```python
   ai_docs = context.get('ai_documentation', {})
   if ai_docs:
       sections = [
           "**Summary:** " + (ai_docs.get('summary', '') or "No summary provided") + "\n\n",
           "**Description:** " + (ai_docs.get('description', '') or "No description provided") + "\n\n"
       ]
   ```

   While the method uses `.get()` to avoid outright key errors, further processing could fail if `ai_docs` is malformed.

### **Potential Issues in `docstring_processor.py`**
1. **Parsing Context**:
   The `parse` method is responsible for converting a docstring (potentially in JSON or plain-string format) into a structured object. If the input `docstring` is malformed or missing key attributes (like `summary`, `returns`, etc.), it could lead to errors in subsequent processing.

   For instance:
   ```python
   if isinstance(docstring, dict):
       return DocstringData(
           summary=docstring.get('summary', ''),
           description=docstring.get('description', ''),
           args=docstring.get('args', []),
           returns=docstring.get('returns', {'type': 'Any', 'description': ''}),
           raises=docstring.get('raises', []),
           complexity=docstring.get('complexity', 1)
       )
   ```
   If `args`, `returns`, or `raises` structures don't match expectations, downstream code might encounter issues.

2. **Failing on Invalid Docstrings**:
   If the `parse` method encounters a docstring format it cannot handle (e.g., an invalid JSON string, malformed docstring structure), it will log an error:
   ```python
   self.logger.error(f"Error parsing docstring: {e}")
   raise DocumentationError(f"Failed to parse docstring: {e}")
   ```

   This won't result in a `KeyError`, but it could propagate through the call stack depending on how this error is handled elsewhere.

### **Root Cause Analysis**
The actual error `ERROR: Error generating documentation: 'module_name'` indicates:
- A **missing or incorrect key (`module_name`) in a dictionary**.
- The failure occurs during the documentation generation process.

As `markdown_generator.py` directly accesses `module_name` via `context['module_name']`, the most likely cause is in this file. Specifically:
- Either `context` is being passed without the required keys in `main.py` or `docs.py`.
- Or the context is being mutated unexpectedly before reaching `markdown_generator.generate()`.

### Debug Recommendations
1. **Log the `context` Before Passing to `generate`**:
   Add logging in `docs.py`:
   ```python
   self.logger.debug(f"Context before markdown generation: {self.context.__dict__}")
   ```

2. **Validate Context Keys in `MarkdownGenerator.generate`**:
   Add explicit validation at the start of `generate()` in `markdown_generator.py`:
   ```python
   required_keys = ['module_name', 'file_path', 'description']
   for key in required_keys:
       if key not in context:
           raise KeyError(f"Missing required key in context: {key}")
   ```

3. **Check `module_name` Injection**:
   Examine all locations in `main.py`, `docs.py`, and `ai_interaction.py` where `module_name` is expected to be added or inherited. Ensure `context['module_name']` is consistently set.

By focusing first on `markdown_generator.py`, you are likely to identify the root issue swiftly.
[Timestamp: 2024/12/03 16:15:42]

**user**: Analyze the provided code extensively to identify the specific area the error is occuring
[Timestamp: 2024/12/03 16:16:55]

**ai**: From analyzing the code provided so far, the error `'module_name'` is likely caused by referencing the `module_name` key in a dictionary (`context`) that does not contain it. Here's a structured and extensive analysis of the potential problem areas where `module_name` is being accessed or expected but might not be present.

---

## **Key Code Paths**

1. **`docs.py` â†’ `DocStringManager.generate_documentation()`**
   - This function interacts with the `markdown_generator` and generates documentation using the `context` dictionary.
   - It creates the `context` object based on the content processed by the `AIInteractionHandler`.

   ```python
   documentation = markdown_generator.generate(self.context.__dict__)
   ```

   - `self.context` includes metadata that should contain `module_name`.
   - If `module_name` is not defined in `self.context.metadata`, this error would occur downstream when accessed in the `MarkdownGenerator`.

---

2. **`main.py` â†’ `DocumentationGenerator.process_file()`**
   - This function is responsible for creating the `context` dictionary that gets passed to `DocStringManager`.

   ```python
   module_name = (
       file_path.stem  # Use the file's stem (e.g., 'example' for 'example.py')
       or file_path.name.split(".")[0]  # Fallback to a basic split
   )
   context = DocumentationContext(
       source_code=updated_code,
       module_path=file_path,
       metadata={
           "file_path": str(file_path),
           "module_name": module_name,  # Explicitly injecting module_name into metadata
           "creation_time": datetime.now().isoformat(),
       },
       ...
   )
   ```

   - The code explicitly assigns `module_name` here.
   - If `file_path.stem` fails (for some reason, such as invalid input), `module_name` would not be set correctly.
   - Later in the `generate_documentation` method of `DocStringManager`, this `module_name` is likely accessed, leading to the error.

---

3. **`markdown_generator.py` â†’ `MarkdownGenerator.generate()`**
   - This method utilizes `context`, which must contain `module_name`.

   Example:
   ```python
   def _generate_header(self, context: Dict[str, Any]) -> str:
       return f"# Module: {context['module_name']}"  # Explicit access to module_name
   ```

   - If `generate()` is invoked with a `context` that lacks `module_name`, a `KeyError` will occur immediately in `_generate_header`.

---

4. **Other Potential Areas**
   - `markdown_generator.py` and `docstring_processor.py` are unlikely to be the root cause unless they receive an invalid or incomplete `context`.
   - These modules do not appear to modify or reconstruct the `context`. Instead, they rely on the input provided to them.

---

## **Root Cause Breakdown**

Given the analysis, the likely cause of the error is in the **construction or modification of `context`**:
   
### **Area 1: `process_file` in `main.py`**
   - The `module_name` key is explicitly defined here:
     ```python
     "module_name": module_name
     ```

   - Possible issues:
     - If `file_path.stem` fails to resolve properly, `module_name` might not be correctly initialized.

### **Area 2: `generate_documentation` in `docs.py`**
   - `self.context.__dict__` should include `module_name` from `self.context.metadata` (defined in `process_file`).

   - Possible issues:
     - If `self.context` is modified incorrectly before being passed to the `MarkdownGenerator`, `module_name` might be removed.

---

## **Steps to Isolate the Error**

1. **Validate Input in `process_file`:**
   ```python
   logger.debug(f"Processing file: {file_path}")

   module_name = (
       file_path.stem
       or file_path.name.split(".")[0]
   )
   logger.debug(f"Module name determined: {module_name}")
   ```

   Ensure that `module_name` is correctly derived from `file_path`.

---

2. **Validate `context` in `generate_documentation` before Passing to `MarkdownGenerator`:**

   Add a debug statement to check the full context dictionary:
   ```python
   logger.debug(f"Context being passed to MarkdownGenerator: {self.context.__dict__}")
   ```

   This will confirm whether `module_name` exists before the call to the `MarkdownGenerator`.

---

3. **Add Validation in `MarkdownGenerator`:**

   At the start of `generate()` in `markdown_generator.py`, validate the required keys:
   ```python
   required_keys = ['module_name', 'file_path', 'description']
   for key in required_keys:
       if key not in context:
           raise KeyError(f"Missing required key in context: {key}")
   ```

   This ensures the error is immediately caught and traced back to where the invalid `context` originated.

---

## **Most Likely Error Location**
The error most likely arises in the following workflows:
1. **In `main.py`**:
   - If `file_path` is invalid (missing or malformed), `module_name` derived from `file_path.stem` will also fail.

2. **In `docs.py`**:
   - If `self.context.metadata` is modified unintentionally or not properly initialized with `module_name`.

---

## **Conclusion**
The error does not appear to originate from the provided `markdown_generator.py` or `docstring_processor.py` logic directly but results from the absence of `module_name` in the `context` passed between `main.py`, `docs.py`, and finally into the `MarkdownGenerator`.

Adding validation and debug logs as outlined will quickly isolate and confirm the root cause of the issue. Would you like to see detailed examples of where and how to add these logs in the code?
[Timestamp: 2024/12/03 16:17:16]